Traceback (most recent call last):
Traceback (most recent call last):
  File "/home/svu/e0833524/CogVideo/finetune/train_cogvideox_lora.py", line 29, in <module>
  File "/home/svu/e0833524/CogVideo/finetune/train_cogvideox_lora.py", line 29, in <module>
Traceback (most recent call last):
  File "/home/svu/e0833524/CogVideo/finetune/train_cogvideox_lora.py", line 29, in <module>
Traceback (most recent call last):
Traceback (most recent call last):
  File "/home/svu/e0833524/CogVideo/finetune/train_cogvideox_lora.py", line 29, in <module>
Traceback (most recent call last):
  File "/home/svu/e0833524/CogVideo/finetune/train_cogvideox_lora.py", line 29, in <module>
  File "/home/svu/e0833524/CogVideo/finetune/train_cogvideox_lora.py", line 29, in <module>
Traceback (most recent call last):
  File "/home/svu/e0833524/CogVideo/finetune/train_cogvideox_lora.py", line 29, in <module>
Traceback (most recent call last):
  File "/home/svu/e0833524/CogVideo/finetune/train_cogvideox_lora.py", line 29, in <module>
    from peft import LoraConfig, get_peft_model_state_dict, set_peft_model_state_dict    
from peft import LoraConfig, get_peft_model_state_dict, set_peft_model_state_dict
ModuleNotFoundError: ModuleNotFoundErrorNo module named 'peft': 
No module named 'peft'    
from peft import LoraConfig, get_peft_model_state_dict, set_peft_model_state_dict    
from peft import LoraConfig, get_peft_model_state_dict, set_peft_model_state_dict
ModuleNotFoundError: ModuleNotFoundError    No module named 'peft': from peft import LoraConfig, get_peft_model_state_dict, set_peft_model_state_dict
No module named 'peft'

ModuleNotFoundError    from peft import LoraConfig, get_peft_model_state_dict, set_peft_model_state_dict
: No module named 'peft'ModuleNotFoundError
:     No module named 'peft'from peft import LoraConfig, get_peft_model_state_dict, set_peft_model_state_dict

ModuleNotFoundError: No module named 'peft'
    from peft import LoraConfig, get_peft_model_state_dict, set_peft_model_state_dict
ModuleNotFoundError: No module named 'peft'
E1017 20:34:13.973000 22656418399360 torch/distributed/elastic/multiprocessing/api.py:833] failed (exitcode: 1) local_rank: 0 (pid: 1835605) of binary: /hpctmp/e0833524/virtualenvs/cogvideo/bin/python
Traceback (most recent call last):
  File "/hpctmp/e0833524/virtualenvs/cogvideo/bin/accelerate", line 8, in <module>
    sys.exit(main())
  File "/hpctmp/e0833524/virtualenvs/cogvideo/lib/python3.10/site-packages/accelerate/commands/accelerate_cli.py", line 48, in main
    args.func(args)
  File "/hpctmp/e0833524/virtualenvs/cogvideo/lib/python3.10/site-packages/accelerate/commands/launch.py", line 1159, in launch_command
    multi_gpu_launcher(args)
  File "/hpctmp/e0833524/virtualenvs/cogvideo/lib/python3.10/site-packages/accelerate/commands/launch.py", line 793, in multi_gpu_launcher
    distrib_run.run(args)
  File "/hpctmp/e0833524/virtualenvs/cogvideo/lib/python3.10/site-packages/torch/distributed/run.py", line 892, in run
    elastic_launch(
  File "/hpctmp/e0833524/virtualenvs/cogvideo/lib/python3.10/site-packages/torch/distributed/launcher/api.py", line 133, in __call__
    return launch_agent(self._config, self._entrypoint, list(args))
  File "/hpctmp/e0833524/virtualenvs/cogvideo/lib/python3.10/site-packages/torch/distributed/launcher/api.py", line 264, in launch_agent
    raise ChildFailedError(
torch.distributed.elastic.multiprocessing.errors.ChildFailedError: 
============================================================
train_cogvideox_lora.py FAILED
------------------------------------------------------------
Failures:
[1]:
  time      : 2024-10-17_20:34:13
  host      : hopper-03.cm.cluster
  rank      : 1 (local_rank: 1)
  exitcode  : 1 (pid: 1835606)
  error_file: <N/A>
  traceback : To enable traceback see: https://pytorch.org/docs/stable/elastic/errors.html
[2]:
  time      : 2024-10-17_20:34:13
  host      : hopper-03.cm.cluster
  rank      : 2 (local_rank: 2)
  exitcode  : 1 (pid: 1835607)
  error_file: <N/A>
  traceback : To enable traceback see: https://pytorch.org/docs/stable/elastic/errors.html
[3]:
  time      : 2024-10-17_20:34:13
  host      : hopper-03.cm.cluster
  rank      : 3 (local_rank: 3)
  exitcode  : 1 (pid: 1835608)
  error_file: <N/A>
  traceback : To enable traceback see: https://pytorch.org/docs/stable/elastic/errors.html
[4]:
  time      : 2024-10-17_20:34:13
  host      : hopper-03.cm.cluster
  rank      : 4 (local_rank: 4)
  exitcode  : 1 (pid: 1835609)
  error_file: <N/A>
  traceback : To enable traceback see: https://pytorch.org/docs/stable/elastic/errors.html
[5]:
  time      : 2024-10-17_20:34:13
  host      : hopper-03.cm.cluster
  rank      : 5 (local_rank: 5)
  exitcode  : 1 (pid: 1835610)
  error_file: <N/A>
  traceback : To enable traceback see: https://pytorch.org/docs/stable/elastic/errors.html
[6]:
  time      : 2024-10-17_20:34:13
  host      : hopper-03.cm.cluster
  rank      : 6 (local_rank: 6)
  exitcode  : 1 (pid: 1835611)
  error_file: <N/A>
  traceback : To enable traceback see: https://pytorch.org/docs/stable/elastic/errors.html
[7]:
  time      : 2024-10-17_20:34:13
  host      : hopper-03.cm.cluster
  rank      : 7 (local_rank: 7)
  exitcode  : 1 (pid: 1835612)
  error_file: <N/A>
  traceback : To enable traceback see: https://pytorch.org/docs/stable/elastic/errors.html
------------------------------------------------------------
Root Cause (first observed failure):
[0]:
  time      : 2024-10-17_20:34:13
  host      : hopper-03.cm.cluster
  rank      : 0 (local_rank: 0)
  exitcode  : 1 (pid: 1835605)
  error_file: <N/A>
  traceback : To enable traceback see: https://pytorch.org/docs/stable/elastic/errors.html
============================================================
