Traceback (most recent call last):
Traceback (most recent call last):
  File "/home/svu/e0833524/CogVideo/finetune/train_cogvideox_lora.py", line 29, in <module>
Traceback (most recent call last):
  File "/home/svu/e0833524/CogVideo/finetune/train_cogvideox_lora.py", line 29, in <module>
  File "/home/svu/e0833524/CogVideo/finetune/train_cogvideox_lora.py", line 29, in <module>
Traceback (most recent call last):
Traceback (most recent call last):
  File "/home/svu/e0833524/CogVideo/finetune/train_cogvideox_lora.py", line 29, in <module>
Traceback (most recent call last):
  File "/home/svu/e0833524/CogVideo/finetune/train_cogvideox_lora.py", line 29, in <module>
  File "/home/svu/e0833524/CogVideo/finetune/train_cogvideox_lora.py", line 29, in <module>
Traceback (most recent call last):
Traceback (most recent call last):
  File "/home/svu/e0833524/CogVideo/finetune/train_cogvideox_lora.py", line 29, in <module>
  File "/home/svu/e0833524/CogVideo/finetune/train_cogvideox_lora.py", line 29, in <module>
    from peft import LoraConfig, get_peft_model_state_dict, set_peft_model_state_dict
ModuleNotFoundError: No module named 'peft'
        from peft import LoraConfig, get_peft_model_state_dict, set_peft_model_state_dictfrom peft import LoraConfig, get_peft_model_state_dict, set_peft_model_state_dict
    
from peft import LoraConfig, get_peft_model_state_dict, set_peft_model_state_dictModuleNotFoundError
ModuleNotFoundError: : No module named 'peft'ModuleNotFoundErrorNo module named 'peft'
: 
No module named 'peft'
    from peft import LoraConfig, get_peft_model_state_dict, set_peft_model_state_dict
    from peft import LoraConfig, get_peft_model_state_dict, set_peft_model_state_dictModuleNotFoundError
: No module named 'peft'
ModuleNotFoundError: No module named 'peft'
        from peft import LoraConfig, get_peft_model_state_dict, set_peft_model_state_dictfrom peft import LoraConfig, get_peft_model_state_dict, set_peft_model_state_dict

ModuleNotFoundErrorModuleNotFoundError: : No module named 'peft'No module named 'peft'

W1016 17:24:27.661000 22441918776448 torch/distributed/elastic/multiprocessing/api.py:858] Sending process 1356749 closing signal SIGTERM
W1016 17:24:27.661000 22441918776448 torch/distributed/elastic/multiprocessing/api.py:858] Sending process 1356750 closing signal SIGTERM
W1016 17:24:27.661000 22441918776448 torch/distributed/elastic/multiprocessing/api.py:858] Sending process 1356751 closing signal SIGTERM
W1016 17:24:27.661000 22441918776448 torch/distributed/elastic/multiprocessing/api.py:858] Sending process 1356752 closing signal SIGTERM
W1016 17:24:27.661000 22441918776448 torch/distributed/elastic/multiprocessing/api.py:858] Sending process 1356754 closing signal SIGTERM
W1016 17:24:27.661000 22441918776448 torch/distributed/elastic/multiprocessing/api.py:858] Sending process 1356755 closing signal SIGTERM
W1016 17:24:27.661000 22441918776448 torch/distributed/elastic/multiprocessing/api.py:858] Sending process 1356756 closing signal SIGTERM
E1016 17:24:27.692000 22441918776448 torch/distributed/elastic/multiprocessing/api.py:833] failed (exitcode: 1) local_rank: 4 (pid: 1356753) of binary: /hpctmp/e0833524/virtualenvs/cogvideo/bin/python
Traceback (most recent call last):
  File "/hpctmp/e0833524/virtualenvs/cogvideo/bin/accelerate", line 8, in <module>
    sys.exit(main())
  File "/hpctmp/e0833524/virtualenvs/cogvideo/lib/python3.10/site-packages/accelerate/commands/accelerate_cli.py", line 48, in main
    args.func(args)
  File "/hpctmp/e0833524/virtualenvs/cogvideo/lib/python3.10/site-packages/accelerate/commands/launch.py", line 1159, in launch_command
    multi_gpu_launcher(args)
  File "/hpctmp/e0833524/virtualenvs/cogvideo/lib/python3.10/site-packages/accelerate/commands/launch.py", line 793, in multi_gpu_launcher
    distrib_run.run(args)
  File "/hpctmp/e0833524/virtualenvs/cogvideo/lib/python3.10/site-packages/torch/distributed/run.py", line 892, in run
    elastic_launch(
  File "/hpctmp/e0833524/virtualenvs/cogvideo/lib/python3.10/site-packages/torch/distributed/launcher/api.py", line 133, in __call__
    return launch_agent(self._config, self._entrypoint, list(args))
  File "/hpctmp/e0833524/virtualenvs/cogvideo/lib/python3.10/site-packages/torch/distributed/launcher/api.py", line 264, in launch_agent
    raise ChildFailedError(
torch.distributed.elastic.multiprocessing.errors.ChildFailedError: 
============================================================
train_cogvideox_lora.py FAILED
------------------------------------------------------------
Failures:
  <NO_OTHER_FAILURES>
------------------------------------------------------------
Root Cause (first observed failure):
[0]:
  time      : 2024-10-16_17:24:27
  host      : hopper-04.cm.cluster
  rank      : 4 (local_rank: 4)
  exitcode  : 1 (pid: 1356753)
  error_file: <N/A>
  traceback : To enable traceback see: https://pytorch.org/docs/stable/elastic/errors.html
============================================================
